<?xml version="1.0"?>

<robot name="single_link_arm">

<link name="world">
</link>

<link name="Motor">
        <visual>
            <origin rpy="1.57 0.0 1.57" xyz="0.026975 0.0 0"/>
            <geometry>
                <mesh filename="package://motor_sim/models/dcMotor.stl"/>
            </geometry>
        </visual>
</link>

<link name="Wheel">
        <visual>
            <origin rpy="1.57 0 -1.57" xyz="0.01 0.0 0"/>
            <geometry>
                <mesh filename="package://motor_sim/models/MCR2_1000_1_1_Wheel_Coupler_2.stl"/>
            </geometry>
        </visual>
</link>

<joint name="joint1" type="fixed">
    <origin xyz="0 0 1" rpy="0 0 0" />
    <parent link="world" />
    <child link="Motor" />
</joint>

<joint name="joint2" type="continuous">
    <origin xyz="0.041475 0 0" rpy="0 0 0" />
    <parent link="Motor" />
    <child link="Wheel" />
    <axis xyz="1 0 0" />
</joint>

</robot>