<?xml version="1.0"?>

<robot name="single_link_arm">

    <link name="world">
    </link>

<link name="Servo">
        <visual>
            <origin rpy="1.57 1.57 0" xyz="0 0 0"/>
            <geometry>
                <mesh filename="package://links_act/models/SG90 - Micro Servo 9g.stl"/>
            </geometry>
        </visual>
</link>

<link name="Attachment">
        <visual>
            <origin rpy="1.57 1.57 0" xyz="0 0 0"/>
            <geometry>
                <mesh filename="package://links_act/models/SG90-Attachment.stl"/>
            </geometry>
        </visual>
</link>


  <joint name="joint1" type="fixed">
    <origin xyz="0 0 1" rpy="0 0 0"/>
    <parent link="world"/>
    <child link="Servo"/>
  </joint>

  <joint name="joint2" type="revolute">
    <origin xyz="0.0211 0 0.00515" rpy="0 0 0"/>
    <parent link="Servo"/>
    <child link="Attachment"/>
    <axis xyz="1 0 0"/>
    <limit lower="-1.57" upper="1.57" effort="5" velocity="2"/>
  </joint>


</robot>