<?xml version="1.0"?>
<robot name="EAI_Robot">


<!-- Dummy link to fiz robot chassis -->
  <link name="base_link">
  </link>
  
    <joint name="chassis_joint" type="fixed">
        <parent link="base_link"/>
        <child link="chassis"/>
        <origin xyz="0.0 0.0 0.11125"/>
    </joint>

    <link name="chassis">
        <visual>
            <origin rpy="0 0 0" xyz="0 0 0"/>
            <geometry>
                <mesh filename="package://dashgo_b1/models/EAIbot_B1.stl"/>
            </geometry>
            <material name="red">
                <color rgba="1.0 0.0 0.0 1.0"/>
            </material>
        </visual>
    </link>


    <link name="wl_link">
        <visual>
            <origin rpy="0.0 0 3.1416" xyz="0 0 0"/>
            <geometry>
                <mesh filename="package://dashgo_b1/models/Wheel.stl"/>
            </geometry>
            <material name="red">
                <color rgba="1.0 0.0 0.0 1.0"/>
            </material>
        </visual>
    </link>


    <link name="wr_link">
        <visual>
            <origin rpy="0 0 3.1416" xyz="0 0 0"/>
            <geometry>
                <mesh filename="package://dashgo_b1/models/Wheel.stl"/>
            </geometry>
            <material name="red">
                <color rgba="1.0 0.0 0.0 1.0"/>
            </material>
        </visual>
    </link>


    <joint name="rightWheel" type="continuous">
        <parent link="chassis"/> 
        <child link="wr_link"/> 
        <origin xyz="0.110026 -0.165 -0.04925" rpy="0 0 0"/>
        <axis xyz="0 1 0"/> 
    </joint>


    <joint name="leftWheel" type="continuous">
        <parent link="chassis"/>
        <child link="wl_link"/>
        <origin xyz="0.110026 0.165 -0.04925" rpy="0 0 0"/>
        <axis xyz="0 1 0"/>
    </joint>


</robot>
